Workbook
Name Dept: RefData!$D$1:$D$20
Name Impact_Sustain: RefData!#REF!
Name Owner_IT: RefData!$E$1:$E$20
Name Plateforme: RefData!$C$1:$C$10
Name Priorité: RefData!$F$1:$F$37
Name TabStatus: TStatus[Status]
Name Type_Projet: RefData!$B$1:$B$5
Name Unité: RefData!$A$1:$A$10

Sheet RefData
A1: Unité | B1: Type de Projet | C1: Plateforme | D1: Dept | E1: Owner IT | F1: Prio | G1: Type Projet | H1: Status | I1: %
A2: CTN | B2: In house | C2: CRP | D2: CAL | E2: Jeanne | F2: 0 | G2: In house | H2: Waiting RFC | I2: 0
A3: SGL | B3: Out sourced | C3: GPAO | D3: IT | E3: Narindra | F3: 1 | G3: In house | H3: RFC approved | I3: 20
A4: CRE | C4: WEB | D4: IND | E4: Angelo | F4: 2 | G4: In house | H4: DEV started | I4: 30
A5: CTN/SGL | C5: SEAM | D5: MPF | E5: Fetra | F5: 3 | G5: In house | H5: Testing | I5: 80
A6: CTN/SGL/CRE | C6: FR-EVOLVE | D6: PRO | E6: Dani | F6: 4 | G6: In house | H6: Debugging | I6: 90
C7: ORACLE | D7: LOG | E7: Jackson | F7: 5 | G7: In house | H7: Go live | I7: 100
C8: PBI | D8: SUS | G8: Out sourced | H8: Prospection | I8: 0
G9: Out sourced | H9: Achat | I9: 30
G10: Out sourced | H10: Installation | I10: 50
G11: Out sourced | H11: Configuration | I11: 60
G12: Out sourced | H12: Data upload | I12: 70
G13: Out sourced | H13: Sécurisation | I13: 80
G14: Out sourced | H14: Formation | I14: 90
G15: Out sourced | H15: Go live | I15: 95
G16: Out sourced | H16: Après vente | I16: 100
G17: In house | H17: Cancelled | I17: 0

Sheet TDC
A1: Unité | B1: CTN
A2: prio | B2: (Tous)
A3: Deadline | B3: (Tous)
A4: % | B4: (Plusieurs éléments)
A6: Étiquettes de lignes | B6: Somme de Ticket #
A7: CAL | B7: 19
A8: IND | B8: 29
A9: IT | B9: 4
A10: MPF | B10: 2
A11: QUA | B11: 1
A12: SUST | B12: 3
A13: CTE | B13: 1
A14: AMG
A15: PO Achat
A16: Total général | B16: 59

Sheet Projets
A1: Unité | B1: Ticket # | C1: # | D1: Projet | E1: Dept | F1: Type de Projet | G1: Plateform | H1: Owner IT | I1: Power user | J1: prio | K1: Dev Volume | L1: Deadline | M1: Status_M1 | N1: Status | O1: Start Date | P1: End Date | Q1: % | R1: Avancement | S1: Commentaire
A2: CTN | B2: 1 | C2: CF006 | D2: Sofab - TT | E2: PRO | F2: In house | G2: GPAO | H2: Fetra | I2: Rehad | J2: TBC | L2: TBC | M2: Waiting RFC | N2: Go live | O2: 45684 | P2: 45954 | Q2: =VLOOKUP(N2,RefData!$H$2:$I$15,2,)/100 -> 1
A3: CTN | B3: 1 | C3: CF023 | D3: Digitalisation de la visite (priorité visite finie) | E3: IND | F3: In house | G3: WEB | H3: Angelo | I3: Tsiky | J3: 3 | L3: S/BY | M3: Formation | N3: Formation | Q3: =VLOOKUP(N3,RefData!$H$2:$I$15,2,)/100 -> 0.9 | R3: dev et test OK finalisation regle de gestion en cours et ergonomie lancer AO et décider oui/non si on va de l'avant | S3: Attente des règles de gestion de la part de l'équipe qualité pour les modifications Application en cours d'utilisation *Toujours en attentes de l'équipe qualité pour l'amelioration *Creation build pour test de la version améliorer *Bloquer au niveau de Tsiky, il n'a pas encore donnée les règles de gestion de sa part *lancement v2 après test iT S/BY PO PW
A4: CTN | B4: 1 | C4: CF055 | D4: Implémentation Orgatex a la teinturefil | E4: IND | F4: Out sourced | H4: Greg | I4: Pascal | J4: 1 | L4: S/BY | M4: DEV started | N4: DEV started | Q4: =VLOOKUP(N4,RefData!$H$2:$I$15,2,)/100 -> 0.3 | R4: sur ex-machine CFL : ok sur machine cotona : attente livraison matériel + venue Technicien S/BY PO Greg
A5: CTN | B5: 1 | C5: CF060 | D5: Digitalisation étude de faisabilité (commentaire live) | E5: PRO | F5: In house | G5: GPAO | H5: Jeanne | I5: Rehad | J5: TBC | K5: Medium | L5: TBC | M5: Waiting RFC | N5: Waiting RFC | Q5: =VLOOKUP(N5,RefData!$H$2:$I$15,2,)/100 -> 0 | R5: Attente mise à jour RFC (Thierry) (inclure Shakil pour lancer projet), faire un email à RH pour aller au bout du projet avec un ticket RFC ( ajout champ commentaire faisabilité + envoi email auto à l'emetteur de FSR)
A6: CTN | C6: CF079 | D6: Envoi colisage et facture automatiquement (paperless) signature electronique | E6: CAL | F6: In house | G6: GPAO | H6: Fetra | I6: Philibert | J6: 0 | L6: TBC | M6: Testing | N6: Go live | O6: 45376 | P6: 45412 | Q6: =VLOOKUP(N6,RefData!$H$2:$I$15,2,)/100 -> 1 | R6: Envoi packing list /facture automatique : synchronisation des données à faire instantanément. Attente feedabck Hoby cal
A7: CTN | B7: 1 | C7: CF094 | D7: Digitalisation fiche lancement commande | E7: PRO | F7: In house | G7: GPAO | H7: Jeanne | I7: Rehad | J7: TBC | K7: Medium | L7: TBC | M7: Waiting RFC | N7: RFC approved | Q7: =VLOOKUP(N7,RefData!$H$2:$I$15,2,)/100 -> 0.2 | R7: attente ajout fonctionnalité de RH, Partie CAL OK
A8: CTN | B8: 1 | C8: CF095 | D8: Modélisation prédictive | E8: IND | H8: Greg | I8: Pascal | J8: 4 | L8: S/BY | M8: Waiting RFC | N8: Waiting RFC | Q8: =VLOOKUP(N8,RefData!$H$2:$I$15,2,)/100 -> 0 | R8: stand by
A9: CTN | B9: 1 | C9: CF101 | D9: Digitalisation de la gestion des camionages (rendu confectionneur Tana/Abe et grand export) | E9: LOG | F9: In house | G9: GPAO | H9: Jeanne | I9: Marc | J9: 2 | L9: S/BY | M9: DEV started | N9: DEV started | Q9: =VLOOKUP(N9,RefData!$H$2:$I$15,2,)/100 -> 0.3 | R9: - Ajout nouvelles fonctionnalités proposées par Tiana/Aurélie/Marc - Groupages des factures en anglais (waiting réunion) S/BY PO Aurélie
A10: CTN | B10: 1 | C10: CF106 | D10: Migration FSR vers MVC | E10: IT | F10: In house | G10: WEB | H10: Fetra | I10: Jeanne | K10: High | L10: TBC | M10: DEV started | N10: Go live | O10: 45359 | P10: 45762 | Q10: =VLOOKUP(N10,RefData!$H$2:$I$15,2,)/100 -> 1 | R10: - Flow (100%) - Create(100%) - Update (100%) - Mail administration (100%) - Reporting (100%)
A11: CTN | C11: CF107 | D11: Migration Sofab MVC + Std de laize | E11: IT | F11: In house | G11: WEB | H11: Fetra | I11: Jeanne | K11: High | L11: TBC | M11: DEV started | N11: Go live | O11: 45359 | P11: 45762 | Q11: 1
A12: CTN | B12: 1 | C12: CF123 | D12: New GPAO | E12: IND | H12: Greg | I12: Pascal + team | J12: 3 | L12: S/BY | M12: Waiting RFC | N12: Waiting RFC | Q12: =VLOOKUP(N12,RefData!$H$2:$I$15,2,)/100 -> 0 | R12: Pascal : Donner synoptique GPAO (visio) Greg : Organisation appel d'offre ( en cours) Datatex : premiere session demo faite. Evalution budget reçue. Solin : a organiser troisieme editeur : ?
A13: CTN | B13: 1 | C13: CF126 | D13: Digitalisation tableau planning tissage dans PBI | E13: IND | H13: Greg | I13: Salohy | J13: 5 | L13: S/BY | M13: Waiting RFC | N13: Waiting RFC | Q13: =VLOOKUP(N13,RefData!$H$2:$I$15,2,)/100 -> 0 | R13: voir pbi cfl existant S/BY PO Shakil
A14: CTN | B14: 1 | C14: CF127a | D14: Traceability: LC/MO bulk sur GPAO | E14: IND | F14: In house | G14: GPAO | H14: Jeanne | I14: Shakil | J14: 0 | L14: TBC | M14: Go live | N14: Go live | O14: 45412 | P14: 45442 | Q14: =VLOOKUP(N14,RefData!$H$2:$I$15,2,)/100 -> 1 | R14: LC/MO par lot fournisseur: . Allocation fils par lot fournisseur (100%) . Mise à jour des stocks fils existant par rapport au lot fournisseur (100%) . Mise à jour des écrans LC/MO par lot fournisseur (100%( . Destockage fil par lot fournisseur (100%)
A15: CTN | B15: 1 | C15: CF127b | D15: Traceability - Supplier platform | E15: SUST | F15: In house | G15: GPAO | H15: Fetra | I15: LP | J15: 0 | L15: TBC | M15: Testing | N15: Go live | O15: 45369 | P15: 45427 | Q15: =VLOOKUP(N15,RefData!$H$2:$I$15,2,)/100 -> 1 | R15: - Supplier Profile (100%) - OCS|GOTS expiration control daily + send mail (100%) - PO's master=> details (100%) - Add login after test (100%)
A16: CTN | B16: 1 | C16: CF127c | D16: Traceability: TC/BCP pour CF et SGL | E16: SUST | F16: In house | G16: WEB | H16: Fetra/Jeanne | I16: LP | J16: 0 | L16: 45397 | M16: DEV started | N16: Go live | O16: 45327 | P16: 45427 | Q16: =VLOOKUP(N16,RefData!$H$2:$I$15,2,)/100 -> 1 | R16: 1- COTONA FABRICS: masse balance BCI (100%) TC organique (100%) . Liaison CRP => GPAO avec verrou et affichage automatique des données de SGL (100%) . Affichage BO SGL dans colisage, facturation, Livraison (100%) . Affichage des données Supplier (100%) . Download infos & Docs pdf . Download data Suppliers (100%) . TC result (100%) . Filtre par: All/waiting BCI/waiting OCS GOTS/waiting TC receipt (100%) . Enregistrement PO CLient CF dans le serveur avec verrou cal (100%) . Fiche des resultats test LABO en report & pdf dans le serveur avec verrou au Labo (100%) . Download auto des proofs of payments dans le plateforme (100%) . Download auto de la fiche à minima dans le plateforme (100%) 2- SOCOTA GARMENTS: BCI (100%) TC (100%) . Download infos & Docs pdf (100%)
A17: CTN | B17: 1 | C17: CF127d | D17: Traceability MCPAT sur GPAO | E17: IND | F17: In house | G17: GPAO | H17: Jeanne | I17: Shakil | J17: 2 | L17: TBC | M17: DEV started | N17: Go live | O17: 45330 | P17: 45473 | Q17: =VLOOKUP(N17,RefData!$H$2:$I$15,2,)/100 -> 1 | R17: . Données ID CARD vers GPAO (100%) . Mise à jour des MCPAT actif/non actif (100%) . Verrou validation bon uniquement pour les MCPAT actifs (100%) . Substitition MCPAT (100%) . Verrou création bon de droguerie uniquement pour les MCPAT actifs (100%) . Création recette dans GPAO pour les MCPAT actifs uniquement (100%) . Verrou saisie de production sans bon de droguerie validé (100%) Attente feedback users (Roger) - MCPAT: .Yarn dyeing 100% .Weaving 100% .At. Blanc 100% .Teinture 100% .Impression 100% .Digital Print 100% .Finishing 100%
A18: CTN | B18: 1 | C18: CF127e | D18: Traceability PO CF dans GPAO | E18: IND | F18: In house | G18: WEB | H18: Fetra/Jeanne | I18: Shakil LP | J18: 2 | L18: S/BY | M18: DEV started | N18: Testing | Q18: =VLOOKUP(N18,RefData!$H$2:$I$15,2,)/100 -> 0.8 | R18: Voir les besoins de chaque département (NEW DESIGN v1.1) - Synchronisation données GPAO vers SALES (100%) - MCPAT - Yarn - Yarn dyeing - Weaving - Finishing - Sales * Envoi facture/PL mutliples (Gouper Facture, Colisage, BT => 1 pdf par facture) (100%) * Corps mail à rajouter : client, retailer, article, style (100%) * Objet mail à rajouter : retailer, article (100%) - Store * Design (100%) * Grouper par PO (100%)
A19: CTN | B19: 1 | C19: CF133 | D19: Migration PLC vers MVC | E19: IT | F19: In house | G19: WEB | H19: Fetra | I19: Jeanne | K19: High | L19: TBC | M19: Testing | N19: Go live | O19: 45810 | P19: 45838 | Q19: =VLOOKUP(N19,RefData!$H$2:$I$15,2,)/100 -> 1 | R19: Fusion du projet vers le portail MVC (100%) | S19: *une grande difference au niveau reporting entre vs2015 et vs 2022 *Amelioration des recherches et filtres pour eviter la lenteur au niveau cahrgement des pages *Solution trouver pour l'adaptation entre les 2 versions *Correction et mis au point PLC avant mis en production *Correction et ajustement vis à vis de plc actuel *Verification et test avant mis en production
A20: CTN | B20: 1 | C20: CF134 | D20: Mail automatique « Waiting FNL » envoyé journalièrement | E20: CAL | F20: In house | G20: GPAO | H20: Jeanne | I20: DB | L20: 45604 | N20: Go live | O20: 45600 | P20: 45602 | Q20: =VLOOKUP(N20,RefData!$H$2:$I$15,2,)/100 -> 1
A21: CTN | B21: 1 | C21: CF135 | D21: Les saisies des raisons seront obligatoires pour les deux cas pour permettre à des analyses ultérieures. Ecran de saisie des causes de retard FNL | E21: CAL | F21: In house | G21: GPAO | H21: Jeanne | I21: DB | L21: 45604 | N21: Go live | O21: 45600 | P21: 45602 | Q21: =VLOOKUP(N21,RefData!$H$2:$I$15,2,)/100 -> 1
A22: CTN | B22: 1 | C22: CF136 | D22: Ecran de saisie / modification des adresses mails clients | E22: CAL | F22: In house | G22: GPAO | H22: Jeanne | I22: DB | L22: 45604 | N22: Go live | O22: 45600 | P22: 45602 | Q22: =VLOOKUP(N22,RefData!$H$2:$I$15,2,)/100 -> 1 | R22: Nous allons créer une base des données des contacts emails de nos clients par contremarque et département. Lesquels seront pris par le système lors de l’envoi de l’alerte aux clients.
A23: CTN | B23: 1 | C23: CF136 | D23: Digitalisation tableau planning - Mise à Dispo Data | E23: IND | F23: In house | G23: GPAO | H23: Jeanne | I23: Shakil | J23: 1 | L23: S/BY | M23: DEV started | N23: DEV started | O23: 45180 | Q23: =VLOOKUP(N23,RefData!$H$2:$I$15,2,)/100 -> 0.3 | R23: - Affichage automatique des LCs par rapport à la date ordo en fonction de la longueur, vitesse et rendement par metier - Drop and drag des bandelettes - Alerte si LC est en retard - Indication du status de chaque LC (planifié, sized, dyed, weaving) S/BY PO Shakil
A24: CTN | B24: 1 | C24: CF137 | D24: Commande avec mise (CT, SU, SO) | E24: IND | F24: In house | G24: GPAO | H24: Jeanne | I24: VA | J24: 0 | N24: Go live | O24: 45625 | P24: 45632 | Q24: =VLOOKUP(N24,RefData!$H$2:$I$15,2,)/100 -> 1 | R24: • Les commandes avec mise seront soldées automatiquement au moment du solde de la mise. • Une alerte sera envoyée au créateur du FSR lorsque la mise est soldée. • Si le ou les A4 ne sont pas reçus au moment du solde de la mise, le commercial coche la case « A4 pas encore reçu ». A leur réception, les commerciaux saisissent la date de réception dans la GPAO. Ces dates seront utilisées pour les analyses futures. • Un mail automatique journalier sera envoyé aux commerciaux et à l’équipe Service Produit pour les attentes A4.
A25: CTN | B25: 1 | C25: CF138 | D25: Commande sans mise (HL, LD, RL, RC, BL | E25: IND | F25: In house | G25: GPAO | H25: Jeanne | I25: VA | J25: 0 | N25: Go live | O25: 45625 | P25: 45632 | Q25: =VLOOKUP(N25,RefData!$H$2:$I$15,2,)/100 -> 1 | R25: • Le Service Produit indique, dans la GPAO, la date de la disponibilité des échantillons avec une alerte mail automatique au commercial. • Cela bascule automatiquement les informations relatives à cette commande d’échantillonnage dans l’écran prévu pour les commerciaux. • Quand tous les paramètres à l’échantillon/développement sont reçus par les commerciaux, ils doivent solder immédiatement la commande échantillonnage en saisissant le mot « COMPLETE » au champ réservé et intitulé « Status ». La date solde générée par le système correspond à la date de réception de l’échantillon/développement. • Sinon le commercial retourne les échantillons/développements au Service Produit et mettre « RETURN » dans la champ « Status » en choisissant la cause du retour (menu déroulant : spectro not received, file not complete, …). • Un mail automatique journalier sera envoyé aux commerciaux et à l’équipe Service Produit pour alerter les commandes attentes solde avec le nombre de jour d’attente.
A26: CTN | B26: 1 | C26: CF139 | D26: La traçabilité (date et user) a été ajouté dans la GPAO pour les nouveaux départements | E26: CAL | F26: In house | G26: GPAO | H26: Jeanne | I26: VA | J26: 0 | N26: Go live | O26: 45622 | P26: 45632 | Q26: =VLOOKUP(N26,RefData!$H$2:$I$15,2,)/100 -> 1
A27: CTN | B27: 1 | C27: CF140 | D27: Upload FSR en masse depuis fichier Excel dans l'appli | E27: Sales | H27: Fetra | I27: Tiana | J27: 1 | L27: Cancel | M27: Waiting RFC | N27: Waiting RFC | Q27: =VLOOKUP(N27,RefData!$H$2:$I$15,2,)/100 -> 0 | R27: - Création matrice d'import des FSR - Rajout fonctionnalité dans FSR pour Tanà seulement - Application des règles avant upload dans la BDD - Formation utilisateur (voir pour creation a partir de template) S/BY PO Greg
A28: CTN | B28: 1 | C28: CF140 | D28: Colisage / facturation automatique | E28: CAL | F28: In house | G28: GPAO | H28: Jeanne | I28: Phil | J28: 0 | N28: Go live | O28: 45642 | P28: 45667 | Q28: =VLOOKUP(N28,RefData!$H$2:$I$15,2,)/100 -> 1
A29: CTN | B29: 1 | C29: CF141 | D29: Integration fichier commande AQL dans GPAO | E29: CAL | F29: In house | G29: GPAO | H29: Jackson | I29: AQL/Dilshad | J29: 0 | L29: 45473 | M29: Waiting RFC | N29: Go live | P29: 45580 | Q29: =VLOOKUP(N29,RefData!$H$2:$I$15,2,)/100 -> 1 | R29: - Definition workflow (Ashwen) - OK - Defintion du dossier paratgé (sharepoint) - OK - Envoi Fichier JSON pour test (Ashwen) - OK - Generation auto JSON dans Sharepoint(Krishna) - OK - JSON Parsing code (Fetra)- OK - Jackson ask to add Retailer, batch number in JSON file (Krishna) - OK
A30: CTN | B30: 1 | C30: CF141 | D30: Remise sur choix AB, AR, AL de BRm Choix B = 50% automatiquement Choix A pas de remise | E30: IND | F30: In house | G30: GPAO | H30: Jeanne | I30: BRm | J30: 0 | N30: Go live | O30: 45634 | P30: 45656 | Q30: =VLOOKUP(N30,RefData!$H$2:$I$15,2,)/100 -> 1
A31: CTN | B31: 1 | C31: CF141bis | D31: Link AIL -> GPAO (new project) | E31: CAL | F31: In house | G31: GPAO | H31: Jeanne | I31: Dilshad | J31: 0 | L31: 45565 | N31: Go live | O31: 45448 | P31: 45473 | Q31: =VLOOKUP(N31,RefData!$H$2:$I$15,2,)/100 -> 1 | R31: - Ajout nouvel champ clé soit mise (bulk) ou PO GPAO (CT) dans WFX (100%) - Update batch JSON (100%) - Récuperation automatique des données GPAO à partir de ce champ clé (100%) - Dev Création automatique de la commande GPAO AIL (100%)
A32: CTN | B32: 1 | C32: CF142 | D32: Envoi donnés Gpao vers AQL | E32: CAL | F32: In house | G32: GPAO | H32: Jackson | I32: AQL/Dilshad | J32: 0 | K32: Low | L32: TBC | M32: Waiting RFC | N32: Go live | P32: 46022 | Q32: =VLOOKUP(N32,RefData!$H$2:$I$15,2,)/100 -> 1 | R32: Attente Feedback Ashwen sur relance du 31/10/24 Ashwen à dit que l'interface est actuellement géré par IA sur la base des Fichier packing list XLS et PDF de CTN 31/08/2025
A33: CTN | B33: 1 | C33: CF142 | D33: Création automatique des notes de crédit par rapport à la remise définie par la Qualité | E33: CAL | F33: In house | G33: GPAO | H33: Jeanne | I33: Phil | J33: 1 | N33: Go live | O33: 45634 | P33: 45664 | Q33: =VLOOKUP(N33,RefData!$H$2:$I$15,2,)/100 -> 1
A34: CTN | B34: 1 | C34: CF143 | D34: Digitalisation de la fiche à minima ==> FSS: Fabric Specification Sheet | E34: QUA | F34: In house | G34: GPAO | H34: Jeanne | I34: VA | J34: 0 | K34: Medium | L34: 45657 | M34: Waiting RFC | N34: Go live | O34: 45622 | P34: 45820 | Q34: =VLOOKUP(N34,RefData!$H$2:$I$15,2,)/100 -> 1 | R34: - Automatisation résultat labo par rapport aux requirements (5%) - Ajouter dans le plateforme FSR la mention obligatoire "Besoin FSS O/N ?" + alerte vers le Labo - Un écran GPAO pour afficher la liste des waiting FSS Et un cochage quand le FSS sera dispo + alerte vers le créateur du FSR - Afficher les blacklists dans la plateforme + export to EXCEL - Mail automatique dès qu'un article a été basculé en blacklist - Faire les FSS et audit SDL pour les 30 articles en best sellers - Digitalisation de la génération FSS (provisoire & définitif) en pdf avec sauvegarde automatique dans le serveur - Fichier excel avec les règles pour Checkers / TBI / Everlane - Liste des « type de garments » – ajuster la liste avec mapping avant après - Ajout des tests inexistants dans GPAO (100%) - Report FSS (provisional & definitive) 100% - Regenerate top 30 best sellers FSS - Data CF commitments => Revalider fichier Excel requirement + upload - Format standard FDS - Le resultat du test (pass/fail) est calculé par le système et non modifiable => Revoir la formule PASS/FAIL dans test result
A35: CTN | B35: 1 | C35: CF143 | D35: Digitalisation planning | E35: IND | F35: In house | G35: GPAO | H35: Jeanne | I35: LP | J35: 0 | K35: Medium | L35: 45747 | N35: Go live | O35: 45634 | P35: 45877 | Q35: =VLOOKUP(N35,RefData!$H$2:$I$15,2,)/100 -> 1 | R35: - Ecrans (02) de lancement - Ecran de planification atelier
A36: CTN | B36: 1 | C36: CF144 | D36: WIP | E36: IND | F36: In house | G36: WEB | H36: Jeanne | I36: LP | J36: 0 | K36: Medium | L36: 45747 | N36: Go live | O36: 45634 | P36: 45887 | Q36: =VLOOKUP(N36,RefData!$H$2:$I$15,2,)/100 -> 1 | R36: - Circuit par mise - Liste des mises par machine - WIP planning
A37: CTN | B37: 1 | C37: CF155 | D37: Digitalisation tableau planning - Front End | E37: PLN | F37: In house | G37: WEB | H37: Angelo | L37: S/BY | M37: Waiting RFC | N37: Waiting RFC | O37: 45208 | Q37: =VLOOKUP(N37,RefData!$H$2:$I$15,2,)/100 -> 0 | R37: Attente filtre avant de test en prod S/BY PO Shakil | S37: reprendre l'application aaprès remarque de Shakil, correction à faire
A38: CTN | B38: 1 | C38: CF157 | D38: Affectation stocks aux commandes | E38: CAL | F38: In house | G38: GPAO | H38: Jeanne | I38: Phil | J38: 0 | L38: TBC | M38: RFC approved | N38: Go live | P38: 45473 | Q38: =VLOOKUP(N38,RefData!$H$2:$I$15,2,)/100 -> 1 | R38: Message à activer si tissu dispo en stock (choix A / AB / AR). La réservaton du stock qu'aura fait le merch déclenchera la déduction du métrage en stock du métrage commandé
A39: CTN | B39: 1 | C39: CF162 | D39: Traçabilité demande de validation validation.socota.com ver 1 | E39: IND | F39: In house | G39: WEB | H39: Angelo | I39: Lovin | M39: Go live | N39: Go live | O39: 45247 | P39: 45369 | Q39: =VLOOKUP(N39,RefData!$H$2:$I$15,2,)/100 -> 1
A40: CTN | B40: 1 | C40: CF167 | D40: Verrouillage lot de fils au Planning | E40: IND | F40: In house | G40: GPAO | H40: Jeanne | I40: Shakil | M40: Go live | N40: Go live | P40: 45300 | Q40: =VLOOKUP(N40,RefData!$H$2:$I$15,2,)/100 -> 1
...

Sheet Tkt
A1: Ticket # | B1: Close Date
A2: 24518 | B2: 45302
A3: 24530 | B3: 45296
A4: 24670 | B4: 45307
A5: 24673 | B5: 45337
A6: 24709 | B6: 45306
A7: 24822 | B7: 45322
A8: 24843 | B8: 45313
A9: 24845 | B9: 45313
A10: 24857 | B10: 45322
A11: 24864 | B11: 45315
A12: 24879 | B12: 45321
A13: 24927 | B13: 45323
... A37: 25746 | B37: 45582
A38: 25768
A39: 25771 | B39: 45400
A40: 25789
A41: 25790 | B41: 45385
A42: 25813 | B42: 45372
A43: 25840 | B43: 45387
A44: 25845 | B44: 45372
A45: 25922 | B45: 45407
A46: 25925 | B46: 45378
A47: 25928 | B47: 45377
A48: 25952 | B48: 45400
A49: 25971 | B49: 45385
A50: 25977 | B50: 45385
A51: 25980 | B51: 45385
A52: 26046 | B52: 45391
... A89: 27321 | B89: 45531
A90: 27355
A91: 27356 | B91: 45484
A92: 27384 | B92: 45485
A93: 27429 | B93: 45489
A94: 27440 | B94: 45491
A95: 27482 | B95: 45496
A96: 27483 | B96: 45503
A97: 27520 | B97: 45495
A98: 27531 | B98: 45496
A99: 27576 | B99: 45498
...
